/usr/local/sbin/startdocker: line 3: /tmp/startdocker.log: Permission denied
/usr/local/sbin/startdocker: line 74: /tmp/startdocker.log: Permission denied
python: can't open file '/gdata/huangzp/dsl_sgen/main': [Errno 2] No such file or directory
/usr/local/sbin/startdocker: line 3: /tmp/startdocker.log: Permission denied
/usr/local/sbin/startdocker: line 74: /tmp/startdocker.log: Permission denied
Unexpected end of /proc/mounts line `overlay / overlay rw,relatime,lowerdir=/home/docker-root/overlay2/l/2MHFVMTTULJ5AYKGLQTJ4LH2MJ:/home/docker-root/overlay2/l/AZKAXIRQMH7POJIQEDKXQI4FIL:/home/docker-root/overlay2/l/IEHICCHRNWVNEFPDII5V4UOVNJ:/home/docker-root/overlay2/l/M2UN22Y23ISVSR35AGR5F5QUWO:/home/docker-root/overlay2/l/5YEGEGXKBZ23DXJGWNEIPLBSFT:/home/docker-root/overlay2/l/A62L5NEWBDNRKNZ4HZ7L2F2KRL:/home/docker-root/overlay2/l/PMEIESVLUFSJ6KH5NU7B3QG3JB:/home/docker-root/overlay2/l/2Z7A4XNYQPC7MVMVOM4RQMHNVW:/home/docker-root/overla'
/usr/local/lib/python3.6/dist-packages/torch/nn/functional.py:1168: UserWarning: Using a target size (torch.Size([32])) that is different to the input size (torch.Size([32, 1])) is deprecated. Please ensure they have the same size.
  "Please ensure they have the same size.".format(target.size(), input.size()))
Traceback (most recent call last):
  File "/gdata/huangzp/dsl_sgen/main.py", line 41, in <module>
    main(config)
  File "/gdata/huangzp/dsl_sgen/main.py", line 33, in main
    trainer.train()
  File "/gdata/huangzp/dsl_sgen/trainer.py", line 329, in train
    l_g = l_gan_A + l_gan_B + 1000*(l_const_A + l_const_B+l_const_AB+l_constBA) + (l_dsl_A + l_dsl_B)
NameError: name 'l_constBA' is not defined
/usr/local/sbin/startdocker: line 3: /tmp/startdocker.log: Permission denied
/usr/local/sbin/startdocker: line 74: /tmp/startdocker.log: Permission denied
Unexpected end of /proc/mounts line `overlay / overlay rw,relatime,lowerdir=/home/docker-root/overlay2/l/S5CNH7UPVTZ4A7Z3O6JLDYBXZZ:/home/docker-root/overlay2/l/AZKAXIRQMH7POJIQEDKXQI4FIL:/home/docker-root/overlay2/l/IEHICCHRNWVNEFPDII5V4UOVNJ:/home/docker-root/overlay2/l/M2UN22Y23ISVSR35AGR5F5QUWO:/home/docker-root/overlay2/l/5YEGEGXKBZ23DXJGWNEIPLBSFT:/home/docker-root/overlay2/l/A62L5NEWBDNRKNZ4HZ7L2F2KRL:/home/docker-root/overlay2/l/PMEIESVLUFSJ6KH5NU7B3QG3JB:/home/docker-root/overlay2/l/2Z7A4XNYQPC7MVMVOM4RQMHNVW:/home/docker-root/overla'
/usr/local/lib/python3.6/dist-packages/torch/nn/functional.py:1168: UserWarning: Using a target size (torch.Size([32])) that is different to the input size (torch.Size([32, 1])) is deprecated. Please ensure they have the same size.
  "Please ensure they have the same size.".format(target.size(), input.size()))
Traceback (most recent call last):
  File "/gdata/huangzp/dsl_sgen/main.py", line 41, in <module>
    main(config)
  File "/gdata/huangzp/dsl_sgen/main.py", line 33, in main
    trainer.train()
  File "/gdata/huangzp/dsl_sgen/trainer.py", line 256, in train
    except StopIteration:
  File "/usr/local/lib/python3.6/dist-packages/torch/utils/data/dataloader.py", line 210, in __next__
    return self._process_next_batch(batch)
  File "/usr/local/lib/python3.6/dist-packages/torch/utils/data/dataloader.py", line 230, in _process_next_batch
    raise batch.exc_type(batch.exc_msg)
RuntimeError: Traceback (most recent call last):
  File "/usr/local/lib/python3.6/dist-packages/torch/utils/data/dataloader.py", line 42, in _worker_loop
    samples = collate_fn([dataset[i] for i in batch_indices])
  File "/usr/local/lib/python3.6/dist-packages/torch/utils/data/dataloader.py", line 94, in default_collate
    storage = batch[0].storage()._new_shared(numel)
  File "/usr/local/lib/python3.6/dist-packages/torch/storage.py", line 113, in _new_shared
    return cls._new_using_fd(size)
RuntimeError: unable to open shared memory object </torch_72_3673427093> in read-write mode at /pytorch/torch/lib/TH/THAllocator.c:278

