Traceback (most recent call last):
  File "../main.py", line 41, in <module>
    main(config)
  File "../main.py", line 27, in main
    config.num_worker, config.skip_pix2pix_processing)
  File "/data1/huangzp/hr_regan/data_loader.py", line 77, in get_loader
    Dataset(root, scale_size, "A", skip_pix2pix_processing), \
  File "/data1/huangzp/hr_regan/data_loader.py", line 50, in __init__
    raise Exception("[!] {} not exists.".format(root))
Exception: [!] data/img_align_celeba not exists.
